<!-- VNR-WH1 — VnRobo Wheeled Humanoid 1
     Version: 0.5.0-bimanual
     DOF: 21 (3 wheels + 2 head + 7L + 7R + 2 grippers)
     v0.5: OpenArm bimanual body_link0 + both arms verbatim from enactic/openarm_mujoco
       - Slim vertical pole replaces crude capsule torso/chest
       - body_link0 = shared back-plate connecting both arms (exact bimanual meshes)
       - Arm chains verbatim from openarm_bimanual.xml (inertials, limits, quats)
       - body_link0 mounted with 90°Z rotation so arms extend ±X (left/right)
-->
<mujoco model="vnr_wh1">

  <compiler angle="radian" meshdir="assets/openarm" inertiafromgeom="auto"/>

  <visual>
    <global offwidth="1920" offheight="1080"/>
  </visual>

  <option gravity="0 0 -9.81" timestep="0.002" integrator="RK4"/>

  <!-- =============================================================== -->
  <!-- DEFAULTS                                                         -->
  <!-- =============================================================== -->
  <default>
    <geom condim="4" friction="1.0 0.005 0.0001" solimp="0.9 0.95 0.001" solref="0.02 1"/>

    <default class="wheel">
      <joint type="hinge" damping="0.3" armature="0.005" limited="false"/>
      <velocity gear="1" ctrlrange="-15 15"/>
    </default>

    <default class="head">
      <joint type="hinge" damping="0.5" armature="0.005" limited="true"/>
      <position kp="50" kv="5"/>
    </default>

    <!-- OpenArm joint physics from bimanual.xml -->
    <default class="motor_DM8009">
      <joint frictionloss="0.1" damping="0.4" limited="true" type="hinge"/>
    </default>
    <default class="motor_DM4340">
      <joint frictionloss="0.1" damping="0.4" limited="true" type="hinge"/>
    </default>
    <default class="motor_DM4310">
      <joint frictionloss="0.1" damping="0.4" limited="true" type="hinge"/>
    </default>
    <default class="motor_finger">
      <joint limited="true" type="slide" damping="2" stiffness="0.5"/>
    </default>

    <!-- Position actuator classes for arm joints -->
    <default class="arm_DM8009">
      <position kp="120" kv="12" forcelimited="true" forcerange="-40 40"/>
    </default>
    <default class="arm_DM4340">
      <position kp="80" kv="8" forcelimited="true" forcerange="-27 27"/>
    </default>
    <default class="arm_DM4310">
      <position kp="50" kv="5" forcelimited="true" forcerange="-7 7"/>
    </default>
    <default class="arm_finger">
      <position kp="100" kv="5" ctrlrange="0 0.044" forcelimited="true" forcerange="-333 333"/>
    </default>

    <!-- Geom display classes (collision disabled for stability) -->
    <default class="visual">
      <geom contype="0" conaffinity="0" group="2" density="0"/>
    </default>
    <default class="collision">
      <geom contype="0" conaffinity="0" group="3" density="0"/>
    </default>
  </default>

  <!-- =============================================================== -->
  <!-- ASSETS                                                           -->
  <!-- =============================================================== -->
  <asset>
    <texture name="grid" type="2d" builtin="checker" rgb1="0.8 0.8 0.8" rgb2="0.6 0.6 0.6"
             width="512" height="512"/>
    <material name="floor_mat"       texture="grid" texrepeat="4 4" reflectance="0.2"/>
    <material name="dark_mat"        rgba="0.15 0.15 0.15 1"/>
    <material name="body_mat"        rgba="0.95 0.62 0.10 1"/>
    <material name="matte_black"     rgba="0.247 0.247 0.247 1" reflectance="0.05" shininess="0.5"/>
    <material name="metal_silver"    rgba="0.796 0.796 0.796 1" reflectance="1.0"  shininess="1.0"/>
    <material name="default_material" rgba="0.7 0.7 0.7 1"/>

    <!-- body_link0 back-plate (6 visual parts + 1 collision) -->
    <mesh name="body_col"  file="collision/body/body_link0.stl" scale="0.001 0.001 0.001"/>
    <mesh name="body_v0"   file="visual/body/body_link0_0.obj"  scale="0.001 0.001 0.001"/>
    <mesh name="body_v1"   file="visual/body/body_link0_1.obj"  scale="0.001 0.001 0.001"/>
    <mesh name="body_v2"   file="visual/body/body_link0_2.obj"  scale="0.001 0.001 0.001"/>
    <mesh name="body_v3"   file="visual/body/body_link0_3.obj"  scale="0.001 0.001 0.001"/>
    <mesh name="body_v4"   file="visual/body/body_link0_4.obj"  scale="0.001 0.001 0.001"/>
    <mesh name="body_v5"   file="visual/body/body_link0_5.obj"  scale="0.001 0.001 0.001"/>

    <!-- Arm collision meshes (right and left-mirror) -->
    <mesh name="link0_col"   file="collision/arm/link0.stl" scale="0.001  0.001 0.001"/>
    <mesh name="link0_col_l" file="collision/arm/link0.stl" scale="0.001 -0.001 0.001"/>
    <mesh name="link1_col"   file="collision/arm/link1.stl" scale="0.001  0.001 0.001"/>
    <mesh name="link1_col_l" file="collision/arm/link1.stl" scale="0.001 -0.001 0.001"/>
    <mesh name="link2_col"   file="collision/arm/link2.stl" scale="0.001  0.001 0.001"/>
    <mesh name="link2_col_l" file="collision/arm/link2.stl" scale="0.001 -0.001 0.001"/>
    <mesh name="link3_col"   file="collision/arm/link3.stl" scale="0.001  0.001 0.001"/>
    <mesh name="link3_col_l" file="collision/arm/link3.stl" scale="0.001 -0.001 0.001"/>
    <mesh name="link4_col"   file="collision/arm/link4.stl" scale="0.001  0.001 0.001"/>
    <mesh name="link5_col"   file="collision/arm/link5.stl" scale="0.001  0.001 0.001"/>
    <mesh name="link5_col_l" file="collision/arm/link5.stl" scale="0.001 -0.001 0.001"/>
    <mesh name="link6_col"   file="collision/arm/link6.stl" scale="0.001  0.001 0.001"/>
    <mesh name="link6_col_l" file="collision/arm/link6.stl" scale="0.001 -0.001 0.001"/>
    <mesh name="link7_col"   file="collision/arm/link7.stl" scale="0.001  0.001 0.001"/>
    <mesh name="link7_col_l" file="collision/arm/link7.stl" scale="0.001 -0.001 0.001"/>
    <mesh name="hand_col"    file="collision/gripper/hand.stl"   scale="0.001 0.001 0.001"/>
    <mesh name="finger_col"  file="collision/gripper/finger.stl" scale="0.001  0.001 0.001"/>
    <mesh name="finger_col_l" file="collision/gripper/finger.stl" scale="0.001 -0.001 0.001"/>

    <!-- Arm visual meshes -->
    <mesh name="link0_v0"  file="visual/arm/link0_0.obj" scale="0.001 0.001 0.001"/>
    <mesh name="link0_v1"  file="visual/arm/link0_1.obj" scale="0.001 0.001 0.001"/>
    <mesh name="link1_v0"  file="visual/arm/link1_0.obj" scale="0.001 0.001 0.001"/>
    <mesh name="link1_v2"  file="visual/arm/link1_2.obj" scale="0.001 0.001 0.001"/>
    <mesh name="link1_v3"  file="visual/arm/link1_3.obj" scale="0.001 0.001 0.001"/>
    <mesh name="link2_v0"  file="visual/arm/link2_0.obj" scale="0.001 0.001 0.001"/>
    <mesh name="link2_v1"  file="visual/arm/link2_1.obj" scale="0.001 0.001 0.001"/>
    <mesh name="link2_v2"  file="visual/arm/link2_2.obj" scale="0.001 0.001 0.001"/>
    <mesh name="link3_v0"  file="visual/arm/link3_0.obj" scale="0.001 0.001 0.001"/>
    <mesh name="link3_v1"  file="visual/arm/link3_1.obj" scale="0.001 0.001 0.001"/>
    <mesh name="link3_v2"  file="visual/arm/link3_2.obj" scale="0.001 0.001 0.001"/>
    <mesh name="link4_v0"  file="visual/arm/link4_0.obj" scale="0.001 0.001 0.001"/>
    <mesh name="link4_v1"  file="visual/arm/link4_1.obj" scale="0.001 0.001 0.001"/>
    <mesh name="link4_v2"  file="visual/arm/link4_2.obj" scale="0.001 0.001 0.001"/>
    <mesh name="link5_v0"  file="visual/arm/link5_0.obj" scale="0.001 0.001 0.001"/>
    <mesh name="link5_v1"  file="visual/arm/link5_1.obj" scale="0.001 0.001 0.001"/>
    <mesh name="link5_v2"  file="visual/arm/link5_2.obj" scale="0.001 0.001 0.001"/>
    <mesh name="link6_v0"  file="visual/arm/link6_0.obj" scale="0.001 0.001 0.001"/>
    <mesh name="link6_v1"  file="visual/arm/link6_1.obj" scale="0.001 0.001 0.001"/>
    <mesh name="link6_v0_l" file="visual/arm/link6_0.obj" scale="0.001 -0.001 0.001"/>
    <mesh name="link6_v1_l" file="visual/arm/link6_1.obj" scale="0.001 -0.001 0.001"/>
    <mesh name="link7_v0"  file="visual/arm/link7_0.obj" scale="0.001 0.001 0.001"/>
    <mesh name="link7_v1"  file="visual/arm/link7_1.obj" scale="0.001 0.001 0.001"/>
    <mesh name="link7_v0_l" file="visual/arm/link7_0.obj" scale="0.001 -0.001 0.001"/>
    <mesh name="link7_v1_l" file="visual/arm/link7_1.obj" scale="0.001 -0.001 0.001"/>
    <mesh name="hand_v0"   file="visual/gripper/hand_0.obj"    scale="0.001 0.001 0.001"/>
    <mesh name="hand_v1"   file="visual/gripper/hand_1.obj"    scale="0.001 0.001 0.001"/>
    <mesh name="finger_v0" file="visual/gripper/finger_0.obj"  scale="0.001  0.001 0.001"/>
    <mesh name="finger_v1" file="visual/gripper/finger_1.obj"  scale="0.001  0.001 0.001"/>
    <mesh name="finger_v0_l" file="visual/gripper/finger_0.obj" scale="0.001 -0.001 0.001"/>
    <mesh name="finger_v1_l" file="visual/gripper/finger_1.obj" scale="0.001 -0.001 0.001"/>
  </asset>

  <!-- =============================================================== -->
  <!-- WORLD                                                            -->
  <!-- =============================================================== -->
  <worldbody>
    <light name="sky"  pos="0 0 5"  dir="0 0 -1"  diffuse="0.8 0.8 0.8" specular="0.3 0.3 0.3" castshadow="false"/>
    <light name="fill" pos="2 -2 3" dir="-1 1 -1" diffuse="0.3 0.3 0.4" specular="0 0 0"       castshadow="false"/>
    <geom name="floor" type="plane" size="8 8 0.1" material="floor_mat" condim="3"/>

    <!-- ======================== BASE PLATFORM ======================== -->
    <!-- base cylinder: r=0.28, h=0.20 → bottom at z=0.10, top at z=0.30 world -->
    <body name="base" pos="0 0 0.20">
      <freejoint name="root"/>
      <geom name="base_geom" type="cylinder" size="0.28 0.10" material="dark_mat" mass="22"/>
      <site name="base_front" pos="0 0.26 0.11" size="0.025" rgba="0.9 0.2 0.2 1"/>
      <site name="imu" pos="0 0 0" size="0.01"/>

      <!-- 3× omni wheels (bottom at z=0.10-0.08=0.02 ≈ floor) -->
      <body name="wheel_f"  pos="0 0.22 -0.12">
        <joint name="wheel_f" class="wheel" axis="1 0 0"/>
        <geom type="cylinder" size="0.080 0.040" zaxis="1 0 0" material="dark_mat" mass="0.8" friction="2 0.01 0.001"/>
        <geom type="cylinder" size="0.055 0.039" zaxis="1 0 0" material="body_mat" mass="0"/>
      </body>
      <body name="wheel_bl" pos="-0.19 -0.11 -0.12">
        <joint name="wheel_bl" class="wheel" axis="-0.5 0.866 0"/>
        <geom type="cylinder" size="0.080 0.040" zaxis="-0.5 0.866 0" material="dark_mat" mass="0.8" friction="2 0.01 0.001"/>
        <geom type="cylinder" size="0.055 0.039" zaxis="-0.5 0.866 0" material="body_mat" mass="0"/>
      </body>
      <body name="wheel_br" pos="0.19 -0.11 -0.12">
        <joint name="wheel_br" class="wheel" axis="0.5 0.866 0"/>
        <geom type="cylinder" size="0.080 0.040" zaxis="0.5 0.866 0" material="dark_mat" mass="0.8" friction="2 0.01 0.001"/>
        <geom type="cylinder" size="0.055 0.039" zaxis="0.5 0.866 0" material="body_mat" mass="0"/>
      </body>

      <!-- ======================== VERTICAL POLE ========================
           Slim dark cylinder: world z=0.30 (base top) → z=0.90
           pole body at z=0.10 above base → z=0.30 world
           geom centered at pole_body+0.30 → cylinder spans z=0.30..0.90 world -->
      <body name="pole" pos="0 0 0.10">
        <inertial pos="0 0 0.30" mass="4.0" diaginertia="0.10 0.10 0.002"/>
        <geom name="pole_geom" type="cylinder" size="0.035 0.30"
              pos="0 0 0.30" material="dark_mat"/>

        <!-- =================== OPENARM BIMANUAL ASSEMBLY =================
             body_link0 = shared back-plate with 6 visual mesh parts
             pos: 0.60 above pole body origin = z=0.90 world
             quat: 90° around Z so body faces +Y, arms extend ±X
             Arm shoulder sockets: z=0.90+0.698=1.598 world (~1.6m)
             ================================================================ -->
        <body name="openarm_body_link0" pos="0 0 0.60" quat="0.7071068 0 0 0.7071068">
          <inertial pos="0.0 0.0 0.0" quat="1.0 0.0 0.0 0.0" mass="13.89"
                    diaginertia="1.653 1.653 0.051"/>
          <geom type="mesh" mesh="body_col" class="collision"/>
          <geom type="mesh" material="matte_black"  mesh="body_v0" class="visual"/>
          <geom type="mesh" material="metal_silver" mesh="body_v1" class="visual"/>
          <geom type="mesh" material="matte_black"  mesh="body_v2" class="visual"/>
          <geom type="mesh" material="matte_black"  mesh="body_v3" class="visual"/>
          <geom type="mesh" material="metal_silver" mesh="body_v4" class="visual"/>
          <geom type="mesh" material="matte_black"  mesh="body_v5" class="visual"/>

          <!-- HEAD: cancel parent 90°Z so head faces +Y, joints work in world frame -->
          <body name="head_pan_link" pos="0 0 0.76" quat="0.7071068 0 0 -0.7071068">
            <joint name="head_pan" class="head" axis="0 0 1" range="-1.57 1.57"/>
            <geom type="cylinder" size="0.042 0.040" material="dark_mat" mass="0.2"/>
            <body name="head" pos="0 0 0.06">
              <joint name="head_tilt" class="head" axis="0 1 0" range="-0.52 0.52"/>
              <geom name="head_geom" type="box" size="0.11 0.09 0.12" material="body_mat" mass="1.5"/>
              <geom name="face_plate" type="box" size="0.09 0.01 0.07"
                    pos="0 0.09 0.01" rgba="0.2 0.2 0.2 1" mass="0"/>
              <site name="cam_rgb"   pos="0 0.10  0.02" size="0.018" rgba="0.1 0.5 0.9 1"/>
              <site name="cam_depth" pos="0 0.10 -0.02" size="0.018" rgba="0.9 0.3 0.1 1"/>
            </body>
          </body>

          <!-- =================== LEFT ARM (verbatim from openarm_bimanual.xml) =================== -->
          <body name="openarm_left_link0" pos="0.0 0.031 0.698"
                quat="0.7071054825112363 -0.7071080798594735 0.0 0.0">
            <inertial pos="-0.0009483362816297526 0.0001580207020448382 0.03076860287587199"
                      quat="1.0 0.0 0.0 0.0" mass="1.1432284943239561"
                      diaginertia="0.001128 0.000962 0.00147"/>
            <geom type="mesh" mesh="link0_col_l" class="collision"/>
            <geom type="mesh" material="metal_silver" mesh="link0_v0" class="visual"/>
            <geom type="mesh" material="matte_black"  mesh="link0_v1" class="visual"/>

            <body name="openarm_left_link1" pos="0.0 0.0 0.0625" quat="1.0 0.0 0.0 0.0">
              <joint name="openarm_left_joint1" class="motor_DM8009"
                     range="-3.490659 1.3962629999999998" axis="0 0 1"/>
              <inertial pos="0.0011467657911800769 3.319987657026362e-05 0.05395284380736254"
                        quat="1.0 0.0 0.0 0.0" mass="1.1416684646202298"
                        diaginertia="0.001567 0.001273 0.001016"/>
              <geom pos="-0.0 0.0 -0.0625" type="mesh" mesh="link1_col_l" class="collision"/>
              <geom pos="-0.0 0.0 -0.0625" type="mesh" material="matte_black" mesh="link1_v0" class="visual"/>
              <geom pos="-0.0 0.0 -0.0625" type="mesh" material="matte_black" mesh="link1_v2" class="visual"/>
              <geom pos="-0.0 0.0 -0.0625" type="mesh" material="matte_black" mesh="link1_v3" class="visual"/>

              <body name="openarm_left_link2" pos="-0.0301 0.0 0.06"
                    quat="0.7071067811882787 -0.7071067811848163 0.0 0.0">
                <joint name="openarm_left_joint2" class="motor_DM8009"
                       range="-3.3161253267948965 0.17453267320510335" axis="-1 0 0"/>
                <inertial pos="0.00839629182351943 -2.0145102027597523e-08 0.03256649300522363"
                          quat="1.0 0.0 0.0 0.0" mass="0.2775092746011571"
                          diaginertia="0.000359 0.000376 0.000232"/>
                <geom pos="0.0301 0.0 -0.1225" type="mesh" mesh="link2_col_l" class="collision"/>
                <geom pos="0.0301 0.0 -0.1225" type="mesh" material="matte_black" mesh="link2_v0" class="visual"/>
                <geom pos="0.0301 0.0 -0.1225" type="mesh" material="matte_black" mesh="link2_v1" class="visual"/>
                <geom pos="0.0301 0.0 -0.1225" type="mesh" material="matte_black" mesh="link2_v2" class="visual"/>

                <body name="openarm_left_link3" pos="0.0301 0.0 0.06625" quat="1.0 0.0 0.0 0.0">
                  <joint name="openarm_left_joint3" class="motor_DM4340"
                         range="-1.570796 1.570796" axis="0 0 1"/>
                  <inertial pos="-0.002104752099628911 0.0005549085042607548 0.08847470545721961"
                            quat="1.0 0.0 0.0 0.0" mass="1.073863338202347"
                            diaginertia="0.004372 0.004319 0.000661"/>
                  <geom pos="-0.0 -0.0 -0.18875" type="mesh" mesh="link3_col_l" class="collision"/>
                  <geom pos="-0.0 -0.0 -0.18875" type="mesh" material="matte_black"  mesh="link3_v0" class="visual"/>
                  <geom pos="-0.0 -0.0 -0.18875" type="mesh" material="matte_black"  mesh="link3_v1" class="visual"/>
                  <geom pos="-0.0 -0.0 -0.18875" type="mesh" material="metal_silver" mesh="link3_v2" class="visual"/>

                  <body name="openarm_left_link4" pos="-0.0 0.0315 0.15375" quat="1.0 0.0 0.0 0.0">
                    <joint name="openarm_left_joint4" class="motor_DM4340"
                           range="0.0 2.443461" axis="0 1 0"/>
                    <inertial pos="-0.0029006831074562967 -0.03030575826634669 0.06339637422196209"
                              quat="1.0 0.0 0.0 0.0" mass="0.6348534566833373"
                              diaginertia="0.001577 0.001346 0.001104"/>
                    <geom pos="0.0 -0.0315 -0.3425" type="mesh" mesh="link4_col" class="collision"/>
                    <geom pos="0.0 -0.0315 -0.3425" type="mesh" material="matte_black"  mesh="link4_v0" class="visual"/>
                    <geom pos="0.0 -0.0315 -0.3425" type="mesh" material="metal_silver" mesh="link4_v1" class="visual"/>
                    <geom pos="0.0 -0.0315 -0.3425" type="mesh" material="matte_black"  mesh="link4_v2" class="visual"/>

                    <body name="openarm_left_link5" pos="0.0 -0.0315 0.0955" quat="1.0 0.0 0.0 0.0">
                      <joint name="openarm_left_joint5" class="motor_DM4310"
                             range="-1.570796 1.570796" axis="0 0 1"/>
                      <inertial pos="-0.003049665024221911 0.0008866902457326625 0.043079803024980934"
                                quat="1.0 0.0 0.0 0.0" mass="0.6156588026168502"
                                diaginertia="0.000423 0.000445 0.000324"/>
                      <geom pos="-0.0 -0.0 -0.438" type="mesh" mesh="link5_col_l" class="collision"/>
                      <geom pos="-0.0 -0.0 -0.438" type="mesh" material="matte_black"  mesh="link5_v0" class="visual"/>
                      <geom pos="-0.0 -0.0 -0.438" type="mesh" material="metal_silver" mesh="link5_v1" class="visual"/>
                      <geom pos="-0.0 -0.0 -0.438" type="mesh" material="matte_black"  mesh="link5_v2" class="visual"/>

                      <body name="openarm_left_link6" pos="0.0375 0.0 0.1205" quat="1.0 0.0 0.0 0.0">
                        <joint name="openarm_left_joint6" class="motor_DM4310"
                               range="-0.785398 0.785398" axis="1 0 0"/>
                        <inertial pos="-0.037136587005447405 0.00033230528343419053 -9.498374522309838e-05"
                                  quat="1.0 0.0 0.0 0.0" mass="0.475202773187987"
                                  diaginertia="0.000143 0.000157 0.000159"/>
                        <geom pos="-0.0375 -0.0 -0.5585" type="mesh" mesh="link6_col_l" class="collision"/>
                        <geom pos="-0.0375 -0.0 -0.5585" type="mesh" material="matte_black"  mesh="link6_v0_l" class="visual"/>
                        <geom pos="-0.0375 -0.0 -0.5585" type="mesh" material="metal_silver" mesh="link6_v1_l" class="visual"/>

                        <body name="openarm_left_link7" pos="-0.0375 0.0 0.0" quat="1.0 0.0 0.0 0.0">
                          <joint name="openarm_left_joint7" class="motor_DM4310"
                                 range="-1.570796 1.570796" axis="0 -1 0"/>
                          <inertial pos="6.875510271106056e-05 -0.01766175250761268 0.06651945409987448"
                                    quat="1.0 0.0 0.0 0.0" mass="0.4659771327380578"
                                    diaginertia="0.000639 0.000497 0.000342"/>
                          <geom pos="0.0 -0.0 -0.5585" type="mesh" mesh="link7_col_l" class="collision"/>
                          <geom pos="0.0 -0.0 -0.5585" type="mesh" material="metal_silver" mesh="link7_v0_l" class="visual"/>
                          <geom pos="0.0 -0.0 -0.5585" type="mesh" material="matte_black"  mesh="link7_v1_l" class="visual"/>

                          <body name="openarm_left_link8" pos="1e-06 0.0205 0.0" quat="1.0 0.0 0.0 0.0">
                            <body name="openarm_left_hand" pos="0 -0.025 0.1001" quat="1.0 0.0 0.0 0.0">
                              <inertial pos="0.0 0.002 0.01" quat="1.0 0.0 0.0 0.0" mass="0.15"
                                        diaginertia="0.0001 0.00025 0.00017"/>
                              <geom pos="0.0 0.005 -0.6585" type="mesh" mesh="hand_col" class="collision"/>
                              <geom pos="0.0 0.005 -0.6585" type="mesh" material="metal_silver" mesh="hand_v0" class="visual"/>
                              <geom pos="0.0 0.005 -0.6585" type="mesh" material="metal_silver" mesh="hand_v1" class="visual"/>
                              <site name="l_tcp" pos="0 0 0.08" size="0.01" rgba="0 1 0 1"/>

                              <body name="openarm_left_right_finger" pos="0 0.00 0.015">
                                <joint name="openarm_left_finger_joint1" class="motor_finger"
                                       range="0.0 0.044" axis="0 -1 0"/>
                                <inertial pos="0.0064528 -0.01702 0.0219685" quat="1.0 0.0 0.0 0.0"
                                          mass="0.03602545343277134"
                                          diaginertia="2.375e-06 2.375e-06 7.5e-07"/>
                                <geom pos="0.0 0.05 -0.673001" type="mesh" mesh="finger_col_l" class="collision"/>
                                <geom pos="0.0 0.05 -0.673001" type="mesh" material="default_material" mesh="finger_v0_l" class="visual"/>
                                <geom pos="0.0 0.05 -0.673001" type="mesh" material="matte_black"    mesh="finger_v1_l" class="visual"/>
                              </body>
                              <body name="openarm_left_left_finger" pos="0 0.012 0.015">
                                <joint name="openarm_left_finger_joint2" class="motor_finger"
                                       range="0.0 0.044" axis="0 1 0"/>
                                <inertial pos="0.0064528 0.01702 0.0219685" quat="1.0 0.0 0.0 0.0"
                                          mass="0.03602545343277134"
                                          diaginertia="2.375e-06 2.375e-06 7.5e-07"/>
                                <geom pos="0.0 -0.05 -0.673001" type="mesh" mesh="finger_col"  class="collision"/>
                                <geom pos="0.0 -0.05 -0.673001" type="mesh" material="default_material" mesh="finger_v0" class="visual"/>
                                <geom pos="0.0 -0.05 -0.673001" type="mesh" material="matte_black"    mesh="finger_v1" class="visual"/>
                              </body>
                            </body>
                          </body>
                        </body>
                      </body>
                    </body>
                  </body>
                </body>
              </body>
            </body>
          </body>

          <!-- =================== RIGHT ARM (verbatim from openarm_bimanual.xml) ================== -->
          <body name="openarm_right_link0" pos="0.0 -0.031 0.698"
                quat="0.7071054825112363 0.7071080798594735 0.0 0.0">
            <inertial pos="-0.0009483362816297526 0.0001580207020448382 0.03076860287587199"
                      quat="1.0 0.0 0.0 0.0" mass="1.1432284943239561"
                      diaginertia="0.001128 0.000962 0.00147"/>
            <geom type="mesh" mesh="link0_col" class="collision"/>
            <geom type="mesh" material="metal_silver" mesh="link0_v0" class="visual"/>
            <geom type="mesh" material="matte_black"  mesh="link0_v1" class="visual"/>

            <body name="openarm_right_link1" pos="0.0 0.0 0.0625" quat="1.0 0.0 0.0 0.0">
              <joint name="openarm_right_joint1" class="motor_DM8009"
                     range="-1.396263 3.490659" axis="0 0 1"/>
              <inertial pos="0.0011467657911800769 3.319987657026362e-05 0.05395284380736254"
                        quat="1.0 0.0 0.0 0.0" mass="1.1416684646202298"
                        diaginertia="0.001567 0.001273 0.001016"/>
              <geom pos="-0.0 0.0 -0.0625" type="mesh" mesh="link1_col" class="collision"/>
              <geom pos="-0.0 0.0 -0.0625" type="mesh" material="matte_black" mesh="link1_v0" class="visual"/>
              <geom pos="-0.0 0.0 -0.0625" type="mesh" material="matte_black" mesh="link1_v2" class="visual"/>
              <geom pos="-0.0 0.0 -0.0625" type="mesh" material="matte_black" mesh="link1_v3" class="visual"/>

              <body name="openarm_right_link2" pos="-0.0301 0.0 0.06"
                    quat="0.7071067811882787 0.7071067811848163 0.0 0.0">
                <joint name="openarm_right_joint2" class="motor_DM8009"
                       range="-0.17453267320510335 3.3161253267948965" axis="-1 0 0"/>
                <inertial pos="0.00839629182351943 -2.0145102027597523e-08 0.03256649300522363"
                          quat="1.0 0.0 0.0 0.0" mass="0.2775092746011571"
                          diaginertia="0.000359 0.000376 0.000232"/>
                <geom pos="0.0301 0.0 -0.1225" type="mesh" mesh="link2_col" class="collision"/>
                <geom pos="0.0301 0.0 -0.1225" type="mesh" material="matte_black" mesh="link2_v0" class="visual"/>
                <geom pos="0.0301 0.0 -0.1225" type="mesh" material="matte_black" mesh="link2_v1" class="visual"/>
                <geom pos="0.0301 0.0 -0.1225" type="mesh" material="matte_black" mesh="link2_v2" class="visual"/>

                <body name="openarm_right_link3" pos="0.0301 0.0 0.06625" quat="1.0 0.0 0.0 0.0">
                  <joint name="openarm_right_joint3" class="motor_DM4340"
                         range="-1.570796 1.570796" axis="0 0 1"/>
                  <inertial pos="-0.002104752099628911 0.0005549085042607548 0.08847470545721961"
                            quat="1.0 0.0 0.0 0.0" mass="1.073863338202347"
                            diaginertia="0.004372 0.004319 0.000661"/>
                  <geom pos="-0.0 -0.0 -0.18875" type="mesh" mesh="link3_col" class="collision"/>
                  <geom pos="-0.0 -0.0 -0.18875" type="mesh" material="matte_black"  mesh="link3_v0" class="visual"/>
                  <geom pos="-0.0 -0.0 -0.18875" type="mesh" material="matte_black"  mesh="link3_v1" class="visual"/>
                  <geom pos="-0.0 -0.0 -0.18875" type="mesh" material="metal_silver" mesh="link3_v2" class="visual"/>

                  <body name="openarm_right_link4" pos="-0.0 0.0315 0.15375" quat="1.0 0.0 0.0 0.0">
                    <joint name="openarm_right_joint4" class="motor_DM4340"
                           range="0.0 2.443461" axis="0 1 0"/>
                    <inertial pos="-0.0029006831074562967 -0.03030575826634669 0.06339637422196209"
                              quat="1.0 0.0 0.0 0.0" mass="0.6348534566833373"
                              diaginertia="0.001577 0.001346 0.001104"/>
                    <geom pos="0.0 -0.0315 -0.3425" type="mesh" mesh="link4_col" class="collision"/>
                    <geom pos="0.0 -0.0315 -0.3425" type="mesh" material="matte_black"  mesh="link4_v0" class="visual"/>
                    <geom pos="0.0 -0.0315 -0.3425" type="mesh" material="metal_silver" mesh="link4_v1" class="visual"/>
                    <geom pos="0.0 -0.0315 -0.3425" type="mesh" material="matte_black"  mesh="link4_v2" class="visual"/>

                    <body name="openarm_right_link5" pos="0.0 -0.0315 0.0955" quat="1.0 0.0 0.0 0.0">
                      <joint name="openarm_right_joint5" class="motor_DM4310"
                             range="-1.570796 1.570796" axis="0 0 1"/>
                      <inertial pos="-0.003049665024221911 0.0008866902457326625 0.043079803024980934"
                                quat="1.0 0.0 0.0 0.0" mass="0.6156588026168502"
                                diaginertia="0.000423 0.000445 0.000324"/>
                      <geom pos="-0.0 -0.0 -0.438" type="mesh" mesh="link5_col" class="collision"/>
                      <geom pos="-0.0 -0.0 -0.438" type="mesh" material="matte_black"  mesh="link5_v0" class="visual"/>
                      <geom pos="-0.0 -0.0 -0.438" type="mesh" material="metal_silver" mesh="link5_v1" class="visual"/>
                      <geom pos="-0.0 -0.0 -0.438" type="mesh" material="matte_black"  mesh="link5_v2" class="visual"/>

                      <body name="openarm_right_link6" pos="0.0375 0.0 0.1205" quat="1.0 0.0 0.0 0.0">
                        <joint name="openarm_right_joint6" class="motor_DM4310"
                               range="-0.785398 0.785398" axis="1 0 0"/>
                        <inertial pos="-0.037136587005447405 0.00033230528343419053 -9.498374522309838e-05"
                                  quat="1.0 0.0 0.0 0.0" mass="0.475202773187987"
                                  diaginertia="0.000143 0.000157 0.000159"/>
                        <geom pos="-0.0375 -0.0 -0.5585" type="mesh" mesh="link6_col" class="collision"/>
                        <geom pos="-0.0375 -0.0 -0.5585" type="mesh" material="matte_black"  mesh="link6_v0" class="visual"/>
                        <geom pos="-0.0375 -0.0 -0.5585" type="mesh" material="metal_silver" mesh="link6_v1" class="visual"/>

                        <body name="openarm_right_link7" pos="-0.0375 0.0 0.0" quat="1.0 0.0 0.0 0.0">
                          <joint name="openarm_right_joint7" class="motor_DM4310"
                                 range="-1.570796 1.570796" axis="0 1 0"/>
                          <inertial pos="6.875510271106056e-05 -0.01766175250761268 0.06651945409987448"
                                    quat="1.0 0.0 0.0 0.0" mass="0.4659771327380578"
                                    diaginertia="0.000639 0.000497 0.000342"/>
                          <geom pos="0.0 -0.0 -0.5585" type="mesh" mesh="link7_col" class="collision"/>
                          <geom pos="0.0 -0.0 -0.5585" type="mesh" material="metal_silver" mesh="link7_v0" class="visual"/>
                          <geom pos="0.0 -0.0 -0.5585" type="mesh" material="matte_black"  mesh="link7_v1" class="visual"/>

                          <body name="openarm_right_link8" pos="1e-06 0.0205 0.0" quat="1.0 0.0 0.0 0.0">
                            <body name="openarm_right_hand" pos="0 -0.025 0.1001" quat="1.0 0.0 0.0 0.0">
                              <inertial pos="0.0 0.002 0.01" quat="1.0 0.0 0.0 0.0" mass="0.15"
                                        diaginertia="0.0001 0.00025 0.00017"/>
                              <geom pos="0.0 0.005 -0.6585" type="mesh" mesh="hand_col" class="collision"/>
                              <geom pos="0.0 0.005 -0.6585" type="mesh" material="metal_silver" mesh="hand_v0" class="visual"/>
                              <geom pos="0.0 0.005 -0.6585" type="mesh" material="metal_silver" mesh="hand_v1" class="visual"/>
                              <site name="r_tcp" pos="0 0 0.08" size="0.01" rgba="0 1 0 1"/>

                              <body name="openarm_right_right_finger" pos="0 0.00 0.015">
                                <joint name="openarm_right_finger_joint1" class="motor_finger"
                                       range="0.0 0.044" axis="0 -1 0"/>
                                <inertial pos="0.0064528 -0.01702 0.0219685" quat="1.0 0.0 0.0 0.0"
                                          mass="0.03602545343277134"
                                          diaginertia="2.375e-06 2.375e-06 7.5e-07"/>
                                <geom pos="0.0 0.05 -0.673001" type="mesh" mesh="finger_col_l" class="collision"/>
                                <geom pos="0.0 0.05 -0.673001" type="mesh" material="default_material" mesh="finger_v0_l" class="visual"/>
                                <geom pos="0.0 0.05 -0.673001" type="mesh" material="matte_black"    mesh="finger_v1_l" class="visual"/>
                              </body>
                              <body name="openarm_right_left_finger" pos="0 0.012 0.015">
                                <joint name="openarm_right_finger_joint2" class="motor_finger"
                                       range="0.0 0.044" axis="0 1 0"/>
                                <inertial pos="0.0064528 0.01702 0.0219685" quat="1.0 0.0 0.0 0.0"
                                          mass="0.03602545343277134"
                                          diaginertia="2.375e-06 2.375e-06 7.5e-07"/>
                                <geom pos="0.0 -0.05 -0.673001" type="mesh" mesh="finger_col"  class="collision"/>
                                <geom pos="0.0 -0.05 -0.673001" type="mesh" material="default_material" mesh="finger_v0" class="visual"/>
                                <geom pos="0.0 -0.05 -0.673001" type="mesh" material="matte_black"    mesh="finger_v1" class="visual"/>
                              </body>
                            </body>
                          </body>
                        </body>
                      </body>
                    </body>
                  </body>
                </body>
              </body>
            </body>
          </body>

        </body> <!-- /openarm_body_link0 -->
      </body> <!-- /pole -->
    </body> <!-- /base -->
  </worldbody>

  <!-- =============================================================== -->
  <!-- TENDON + EQUALITY (gripper coupling)                             -->
  <!-- =============================================================== -->
  <tendon>
    <fixed name="split_left">
      <joint joint="openarm_left_finger_joint1"  coef="0.5"/>
      <joint joint="openarm_left_finger_joint2"  coef="0.5"/>
    </fixed>
    <fixed name="split_right">
      <joint joint="openarm_right_finger_joint1" coef="0.5"/>
      <joint joint="openarm_right_finger_joint2" coef="0.5"/>
    </fixed>
  </tendon>

  <equality>
    <joint joint1="openarm_left_finger_joint1"  joint2="openarm_left_finger_joint2"
           solimp="0.95 0.99 0.001" solref="0.005 1"/>
    <joint joint1="openarm_right_finger_joint1" joint2="openarm_right_finger_joint2"
           solimp="0.95 0.99 0.001" solref="0.005 1"/>
  </equality>

  <!-- =============================================================== -->
  <!-- ACTUATORS                                                        -->
  <!-- =============================================================== -->
  <actuator>
    <!-- Wheels -->
    <velocity name="wheel_f"  joint="wheel_f"  class="wheel"/>
    <velocity name="wheel_bl" joint="wheel_bl" class="wheel"/>
    <velocity name="wheel_br" joint="wheel_br" class="wheel"/>

    <!-- Head -->
    <position name="head_pan"  joint="head_pan"  class="head" ctrlrange="-1.57 1.57"/>
    <position name="head_tilt" joint="head_tilt" class="head" ctrlrange="-0.52 0.52"/>

    <!-- Left arm -->
    <position name="l_j1" joint="openarm_left_joint1" class="arm_DM8009" ctrlrange="-3.490659 1.396263"/>
    <position name="l_j2" joint="openarm_left_joint2" class="arm_DM8009" ctrlrange="-3.316125 0.174533"/>
    <position name="l_j3" joint="openarm_left_joint3" class="arm_DM4340" ctrlrange="-1.570796 1.570796"/>
    <position name="l_j4" joint="openarm_left_joint4" class="arm_DM4340" ctrlrange="0.0 2.443461"/>
    <position name="l_j5" joint="openarm_left_joint5" class="arm_DM4310" ctrlrange="-1.570796 1.570796"/>
    <position name="l_j6" joint="openarm_left_joint6" class="arm_DM4310" ctrlrange="-0.785398 0.785398"/>
    <position name="l_j7" joint="openarm_left_joint7" class="arm_DM4310" ctrlrange="-1.570796 1.570796"/>
    <position name="l_grip" joint="openarm_left_finger_joint1" class="arm_finger"/>

    <!-- Right arm -->
    <position name="r_j1" joint="openarm_right_joint1" class="arm_DM8009" ctrlrange="-1.396263 3.490659"/>
    <position name="r_j2" joint="openarm_right_joint2" class="arm_DM8009" ctrlrange="-0.174533 3.316125"/>
    <position name="r_j3" joint="openarm_right_joint3" class="arm_DM4340" ctrlrange="-1.570796 1.570796"/>
    <position name="r_j4" joint="openarm_right_joint4" class="arm_DM4340" ctrlrange="0.0 2.443461"/>
    <position name="r_j5" joint="openarm_right_joint5" class="arm_DM4310" ctrlrange="-1.570796 1.570796"/>
    <position name="r_j6" joint="openarm_right_joint6" class="arm_DM4310" ctrlrange="-0.785398 0.785398"/>
    <position name="r_j7" joint="openarm_right_joint7" class="arm_DM4310" ctrlrange="-1.570796 1.570796"/>
    <position name="r_grip" joint="openarm_right_finger_joint1" class="arm_finger"/>
  </actuator>

  <!-- =============================================================== -->
  <!-- CONTACT EXCLUSIONS                                               -->
  <!-- =============================================================== -->
  <contact>
    <exclude body1="pole"             body2="openarm_body_link0"/>
    <exclude body1="openarm_body_link0" body2="openarm_left_link0"/>
    <exclude body1="openarm_body_link0" body2="openarm_right_link0"/>
    <!-- Left arm adjacency -->
    <exclude body1="openarm_left_link0" body2="openarm_left_link1"/>
    <exclude body1="openarm_left_link0" body2="openarm_left_link2"/>
    <exclude body1="openarm_left_link0" body2="openarm_left_link3"/>
    <exclude body1="openarm_left_link1" body2="openarm_left_link2"/>
    <exclude body1="openarm_left_link1" body2="openarm_left_link3"/>
    <exclude body1="openarm_left_link2" body2="openarm_left_link3"/>
    <exclude body1="openarm_left_link3" body2="openarm_left_link4"/>
    <exclude body1="openarm_left_link4" body2="openarm_left_link5"/>
    <exclude body1="openarm_left_link5" body2="openarm_left_link6"/>
    <exclude body1="openarm_left_link5" body2="openarm_left_link7"/>
    <exclude body1="openarm_left_link6" body2="openarm_left_link7"/>
    <exclude body1="openarm_left_hand"  body2="openarm_left_right_finger"/>
    <exclude body1="openarm_left_hand"  body2="openarm_left_left_finger"/>
    <!-- Right arm adjacency -->
    <exclude body1="openarm_right_link0" body2="openarm_right_link1"/>
    <exclude body1="openarm_right_link0" body2="openarm_right_link2"/>
    <exclude body1="openarm_right_link0" body2="openarm_right_link3"/>
    <exclude body1="openarm_right_link1" body2="openarm_right_link2"/>
    <exclude body1="openarm_right_link1" body2="openarm_right_link3"/>
    <exclude body1="openarm_right_link2" body2="openarm_right_link3"/>
    <exclude body1="openarm_right_link3" body2="openarm_right_link4"/>
    <exclude body1="openarm_right_link4" body2="openarm_right_link5"/>
    <exclude body1="openarm_right_link5" body2="openarm_right_link6"/>
    <exclude body1="openarm_right_link5" body2="openarm_right_link7"/>
    <exclude body1="openarm_right_link6" body2="openarm_right_link7"/>
    <exclude body1="openarm_right_hand"  body2="openarm_right_right_finger"/>
    <exclude body1="openarm_right_hand"  body2="openarm_right_left_finger"/>
  </contact>

</mujoco>
